#VRML_SIM R2022a utf8
WorldInfo {
}
Viewpoint {
  orientation -0.2451390996441338 -0.8205949350228142 0.5162661856451249 5.209923019598004
  position -1.8798309478842794 1.0635452340717235 2.6028041811130636
}
TexturedBackground {
}
TexturedBackgroundLight {
}
WoodenBox {
  translation 0 -0.3 0.04
  size 0.1 0.1 0.1
}
WoodenBox {
  translation 0.28 0.01 0.04
  name "wooden box(1)"
  size 0.1 0.1 0.1
}
E-puck {
  translation -0.06217863818328997 0.3581439568701607 -0.00011006653505186634
  rotation 0.0003192250768242524 -0.0002171472747282256 0.999999925471203 -0.4457312338232846
  controller "epuck_collisionavoidance_ck"
}
Floor {
  size 1 1
}
Solid {
  translation -0.29 0 0.09342619472746846
  rotation 0 1 0 0
  children [
    Shape {
      appearance PBRAppearance {
        roughness 1
        metalness 0
      }
      geometry Sphere {
        radius 0.1
      }
    }
  ]
  boundingObject Sphere {
    radius 0.1
  }
  physics Physics {
  }
}
DEF WALL-SOLID Solid {
  translation 0 -0.45 0
  children [
    DEF WALL Shape {
      appearance PBRAppearance {
        baseColor 0 0 0
      }
      geometry Box {
        size 0.9 0.1 0.1
      }
    }
  ]
  name "solid(1)"
}
Solid {
  translation 0.45 4.58822e-07 0
  rotation 0 0 1 -1.5707953071795862
  children [
    USE WALL
  ]
  name "solid(2)"
}
Solid {
  translation -0.45 -1.65291e-06 0
  rotation 0 0 1 1.5708
  children [
    USE WALL
  ]
  name "solid(3)"
}
Solid {
  translation 0 0.45 0
  children [
    USE WALL
  ]
  name "solid(4)"
}
Robot {
  children [
    DEF WHEEL1 HingeJoint {
      jointParameters HingeJointParameters {
        axis 0 1 0
        anchor 0.05 0.06 0
      }
      device [
        RotationalMotor {
          name "wheel1"
        }
      ]
      endPoint Solid {
        translation 0.05 0.06 0
        rotation 1 0 0 1.5708
        children [
          DEF WHEEL Shape {
            appearance PBRAppearance {
              baseColor 0.305882 0.898039 0.25098
              roughness 1
              metalness 0
            }
            geometry Cylinder {
              height 0.02
              radius 0.04
              subdivision 24
            }
          }
        ]
        boundingObject USE WHEEL
        physics Physics {
        }
      }
    }
    DEF WHEEL2 HingeJoint {
      jointParameters HingeJointParameters {
        axis 0 1 0
        anchor 0.05 -0.06 0
      }
      device [
        RotationalMotor {
          name "wheel2"
        }
      ]
      endPoint Solid {
        translation 0.05 -0.06 0
        rotation 1 0 0 1.5708
        children [
          USE WHEEL
        ]
        name "solid(1)"
        boundingObject USE WHEEL
        physics Physics {
        }
      }
    }
    DEF WHEEL3 HingeJoint {
      jointParameters HingeJointParameters {
        axis 0 1 0
        anchor -0.05 0.06 0
      }
      device [
        RotationalMotor {
          name "wheel3"
        }
      ]
      endPoint Solid {
        translation -0.05 0.06 0
        rotation 1 0 0 1.5708
        children [
          USE WHEEL
        ]
        name "solid(2)"
        boundingObject USE WHEEL
        physics Physics {
        }
      }
    }
    DEF WHEEL4 HingeJoint {
      jointParameters HingeJointParameters {
        axis 0 1 0
        anchor -0.05 -0.06 0
      }
      device [
        RotationalMotor {
          name "wheel4"
        }
      ]
      endPoint Solid {
        translation -0.05 -0.06 0
        rotation 1 0 0 1.5708
        children [
          USE WHEEL
        ]
        name "solid(3)"
        boundingObject USE WHEEL
        physics Physics {
        }
      }
    }
    DEF DSLEFT DistanceSensor {
      translation 0.1 0.025 0.01
      rotation 0 0 1 0.3
      children [
        Shape {
          geometry Box {
            size 0.01 0.01 0.01
          }
        }
      ]
      name "ds_left"
    }
    DEF DSRIGHT DistanceSensor {
      translation 0.1 -0.025 0.01
      rotation 0 0 -1 0.3
      children [
        Shape {
          geometry Box {
            size 0.01 0.01 0.01
          }
        }
      ]
      name "ds_right"
    }
    DEF BODY Shape {
      appearance PBRAppearance {
        baseColor 0.643137 0 0
      }
      geometry Box {
        size 0.2 0.1 0.05
      }
    }
  ]
  name "4Wheeler"
  boundingObject USE BODY
  physics Physics {
    density -1
    mass 1
  }
  controller "fourwheeler_ck"
}
